<?xml version="1.0" ?>
<!-- =================================================================================== -->
<!-- |    This document was autogenerated by xacro from /home/alexoberco/Escritorio/ros2_ws/src/urfi_description/urdf/robot_model.xacro.urdf | -->
<!-- |    EDITING THIS FILE BY HAND IS NOT RECOMMENDED                                 | -->
<!-- =================================================================================== -->
<robot name="robot_model">
  <material name="yellow">
    <color rgba="1 0.95 0 1"/>
  </material>
  <material name="blue">
    <color rgba="0 0 1 1"/>
  </material>
  <material name="light_blue">
    <color rgba="0 0.5 0.8 1"/>
  </material>
  <material name="black">
    <color rgba="0 0 0 1"/>
  </material>
  <material name="white">
    <color rgba="1 1 1 1"/>
  </material>
  <material name="red">
    <color rgba="0.8 0.0 0.0 1.0"/>
  </material>
  <material name="silver">
    <color rgba="0.79 0.82 0.93 1"/>
  </material>
  <material name="dark_grey">
    <color rgba="0.3 0.3 0.3 1"/>
  </material>
  <link name="base_footprint"/>
  <joint name="base_joint" type="fixed">
    <parent link="base_footprint"/>
    <child link="base_link"/>
    <origin rpy="0.0 0.0 0.0" xyz="0.0 0.0 0.1"/>
  </joint>
  <link name="base_link">
    <visual>
      <origin rpy="1.5708 0.0 1.5708" xyz="0.0 0.0 0.0"/>
      <geometry>
        <box size="0.3 0.1 0.7"/>
      </geometry>
      <material name="blue"/>
    </visual>
    <collision>
      <origin rpy="0.0 0.0 0.0" xyz="0.0 0.0 0.0"/>
      <geometry>
        <box size="0.7 0.3 0.1"/>
      </geometry>
    </collision>
    <inertial>
      <origin rpy="0.0 0.0 0.0" xyz="0.0 0.0 0.0"/>
      <mass value="19.95"/>
      <inertia ixx="0.8312499999999998" ixy="0" ixz="0" iyy="0.9642499999999998" iyz="0" izz="0.16625"/>
    </inertial>
  </link>
  <link name="right_1_wheel">
    <visual>
      <origin rpy="1.5707963267948966 0 0" xyz="0 -0.075 0"/>
      <geometry>
        <mesh filename="file:///home/alexoberco/Escritorio/ros2_ws/src/urfi_description/meshes/wheel.stl" scale="0.075 0.075 0.075"/>
      </geometry>
      <material name="dark_grey"/>
    </visual>
    <collision>
      <origin rpy="1.5707963267948966 0 0" xyz="0 -0.0375 0"/>
      <geometry>
        <cylinder length="0.075" radius="0.1"/>
      </geometry>
    </collision>
    <inertial>
      <origin rpy="0.0 0.0 0.0" xyz="0.0 0.0 0.0"/>
      <mass value="119.76"/>
      <inertia ixx="0.08607750000000002" ixy="0" ixz="0" iyy="0.08607750000000002" iyz="0" izz="0.06880000000000008"/>
    </inertial>
  </link>
  <joint name="right_1_wheel_joint" type="continuous">
    <axis rpy="0 0 0" xyz="0 1 0"/>
    <parent link="base_link"/>
    <child link="right_1_wheel"/>
    <origin rpy="0 0.0 0" xyz="0.25 -0.15 0"/>
    <dynamics damping="0.01" friction="0.0"/>
  </joint>
  <link name="left_1_wheel">
    <visual>
      <origin rpy="-1.5707963267948966 0 0" xyz="0 0.075 0"/>
      <geometry>
        <mesh filename="file:///home/alexoberco/Escritorio/ros2_ws/src/urfi_description/meshes/wheel.stl" scale="0.075 0.075 0.075"/>
      </geometry>
      <material name="dark_grey"/>
    </visual>
    <collision>
      <origin rpy="1.5707963267948966 0 0" xyz="0 0.0375 0"/>
      <geometry>
        <cylinder length="0.075" radius="0.1"/>
      </geometry>
    </collision>
    <inertial>
      <origin rpy="0.0 0.0 0.0" xyz="0.0 0.0 0.0"/>
      <mass value="119.76"/>
      <inertia ixx="0.08607750000000002" ixy="0" ixz="0" iyy="0.08607750000000002" iyz="0" izz="0.06880000000000008"/>
    </inertial>
  </link>
  <joint name="left_1_wheel_joint" type="continuous">
    <axis rpy="0 0 0" xyz="0 1 0"/>
    <parent link="base_link"/>
    <child link="left_1_wheel"/>
    <origin rpy="0 0.0 0" xyz="0.25 0.15 0"/>
    <dynamics damping="0.01" friction="0.0"/>
  </joint>
  <link name="left_2_wheel">
    <visual>
      <origin rpy="-1.5707963267948966 0 0" xyz="0 0.075 0"/>
      <geometry>
        <mesh filename="file:///home/alexoberco/Escritorio/ros2_ws/src/urfi_description/meshes/wheel.stl" scale="0.075 0.075 0.075"/>
      </geometry>
      <material name="dark_grey"/>
    </visual>
    <collision>
      <origin rpy="1.5707963267948966 0 0" xyz="0 0.0375 0"/>
      <geometry>
        <cylinder length="0.075" radius="0.1"/>
      </geometry>
    </collision>
    <inertial>
      <origin rpy="0.0 0.0 0.0" xyz="0.0 0.0 0.0"/>
      <mass value="119.76"/>
      <inertia ixx="0.08607750000000002" ixy="0" ixz="0" iyy="0.08607750000000002" iyz="0" izz="0.06880000000000008"/>
    </inertial>
  </link>
  <joint name="left_2_wheel_joint" type="continuous">
    <axis rpy="0 0 0" xyz="0 1 0"/>
    <parent link="base_link"/>
    <child link="left_2_wheel"/>
    <origin rpy="0 0.0 0" xyz="0.0 0.15 0"/>
    <dynamics damping="0.01" friction="0.0"/>
  </joint>
  <link name="right_2_wheel">
    <visual>
      <origin rpy="1.5707963267948966 0 0" xyz="0 -0.075 0"/>
      <geometry>
        <mesh filename="file:///home/alexoberco/Escritorio/ros2_ws/src/urfi_description/meshes/wheel.stl" scale="0.075 0.075 0.075"/>
      </geometry>
      <material name="dark_grey"/>
    </visual>
    <collision>
      <origin rpy="1.5707963267948966 0 0" xyz="0 -0.0375 0"/>
      <geometry>
        <cylinder length="0.075" radius="0.1"/>
      </geometry>
    </collision>
    <inertial>
      <origin rpy="0.0 0.0 0.0" xyz="0.0 0.0 0.0"/>
      <mass value="119.76"/>
      <inertia ixx="0.08607750000000002" ixy="0" ixz="0" iyy="0.08607750000000002" iyz="0" izz="0.06880000000000008"/>
    </inertial>
  </link>
  <joint name="right_2_wheel_joint" type="continuous">
    <axis rpy="0 0 0" xyz="0 1 0"/>
    <parent link="base_link"/>
    <child link="right_2_wheel"/>
    <origin rpy="0 0.0 0" xyz="0.0 -0.15 0"/>
    <dynamics damping="0.01" friction="0.0"/>
  </joint>
  <link name="left_3_wheel">
    <visual>
      <origin rpy="-1.5707963267948966 0 0" xyz="0 0.075 0"/>
      <geometry>
        <mesh filename="file:///home/alexoberco/Escritorio/ros2_ws/src/urfi_description/meshes/wheel.stl" scale="0.075 0.075 0.075"/>
      </geometry>
      <material name="dark_grey"/>
    </visual>
    <collision>
      <origin rpy="1.5707963267948966 0 0" xyz="0 0.0375 0"/>
      <geometry>
        <cylinder length="0.075" radius="0.1"/>
      </geometry>
    </collision>
    <inertial>
      <origin rpy="0.0 0.0 0.0" xyz="0.0 0.0 0.0"/>
      <mass value="119.76"/>
      <inertia ixx="0.08607750000000002" ixy="0" ixz="0" iyy="0.08607750000000002" iyz="0" izz="0.06880000000000008"/>
    </inertial>
  </link>
  <joint name="left_3_wheel_joint" type="continuous">
    <axis rpy="0 0 0" xyz="0 1 0"/>
    <parent link="base_link"/>
    <child link="left_3_wheel"/>
    <origin rpy="0 0.0 0" xyz="-0.25 0.15 0"/>
    <dynamics damping="0.01" friction="0.0"/>
  </joint>
  <link name="right_3_wheel">
    <visual>
      <origin rpy="1.5707963267948966 0 0" xyz="0 -0.075 0"/>
      <geometry>
        <mesh filename="file:///home/alexoberco/Escritorio/ros2_ws/src/urfi_description/meshes/wheel.stl" scale="0.075 0.075 0.075"/>
      </geometry>
      <material name="dark_grey"/>
    </visual>
    <collision>
      <origin rpy="1.5707963267948966 0 0" xyz="0 -0.0375 0"/>
      <geometry>
        <cylinder length="0.075" radius="0.1"/>
      </geometry>
    </collision>
    <inertial>
      <origin rpy="0.0 0.0 0.0" xyz="0.0 0.0 0.0"/>
      <mass value="119.76"/>
      <inertia ixx="0.08607750000000002" ixy="0" ixz="0" iyy="0.08607750000000002" iyz="0" izz="0.06880000000000008"/>
    </inertial>
  </link>
  <joint name="right_3_wheel_joint" type="continuous">
    <axis rpy="0 0 0" xyz="0 1 0"/>
    <parent link="base_link"/>
    <child link="right_3_wheel"/>
    <origin rpy="0 0.0 0" xyz="-0.25 -0.15 0"/>
    <dynamics damping="0.01" friction="0.0"/>
  </joint>
  <ros2_control name="IgnitionSystem" type="system">
    <hardware>
      <plugin>ign_ros2_control/IgnitionSystem</plugin>
    </hardware>
    <joint name="left_1_wheel_joint">
      <command_interface name="velocity">
        <param name="min">-5</param>
        <param name="max">5</param>
      </command_interface>
      <state_interface name="position"/>
      <state_interface name="velocity"/>
    </joint>
    <joint name="right_1_wheel_joint">
      <command_interface name="velocity">
        <param name="min">-5</param>
        <param name="max">5</param>
      </command_interface>
      <state_interface name="position"/>
      <state_interface name="velocity"/>
    </joint>
    <joint name="left_2_wheel_joint">
      <command_interface name="velocity">
        <param name="min">-5</param>
        <param name="max">5</param>
      </command_interface>
      <state_interface name="position"/>
      <state_interface name="velocity"/>
    </joint>
    <joint name="right_2_wheel_joint">
      <command_interface name="velocity">
        <param name="min">-5</param>
        <param name="max">5</param>
      </command_interface>
      <state_interface name="position"/>
      <state_interface name="velocity"/>
    </joint>
    <joint name="left_3_wheel_joint">
      <command_interface name="velocity">
        <param name="min">-5</param>
        <param name="max">5</param>
      </command_interface>
      <state_interface name="position"/>
      <state_interface name="velocity"/>
    </joint>
    <joint name="right_3_wheel_joint">
      <command_interface name="velocity">
        <param name="min">-5</param>
        <param name="max">5</param>
      </command_interface>
      <state_interface name="position"/>
      <state_interface name="velocity"/>
    </joint>
  </ros2_control>
  <gazebo>
    <!-- Joint state publisher -->
    <plugin filename="ign_ros2_control-system" name="ign_ros2_control::IgnitionROS2ControlPlugin">
      <parameters>/home/alexoberco/Escritorio/ros2_ws/install/urfi_control/share/urfi_control/config/urfi_controllers.yaml</parameters>
    </plugin>
  </gazebo>
</robot>
